<?xml version="1.0" encoding="utf-8"?>

<robot
  name="diff_offset_robot">
  <link
    name="base_link">
    <inertial>
      <origin
        xyz="0.027195 -1.382E-07 1.4192E-05"
        rpy="0 0 0" />
      <mass
        value="7.7306" />
      <inertia
        ixx="0.08923"
        ixy="-1.6849E-17"
        ixz="-0.00013721"
        iyy="0.12656"
        iyz="-1.6354E-19"
        izz="0.21251" />
    </inertial>
    <visual>
      <origin
        xyz="0 0 0"
        rpy="0 0 0" />
      <geometry>
        <mesh
          filename="package://model_robot/meshes/base_link.STL" />
      </geometry>
      <material
        name="">
        <color
          rgba="0.79216 0.81961 0.93333 1" />
      </material>
    </visual>
    <collision>
      <origin
        xyz="0 0 0"
        rpy="0 0 0" />
      <geometry>
        <mesh
          filename="package://model_robot/meshes/base_link.STL" />
      </geometry>
    </collision>
  </link>
  <link
    name="left_wheel_link">
    <inertial>
      <origin
        xyz="-2.2204E-16 -3.2613E-16 0.04781"
        rpy="0 0 0" />
      <mass
        value="0.37174" />
      <inertia
        ixx="0.00039822"
        ixy="-1.2163E-18"
        ixz="-3.573E-19"
        iyy="0.00039822"
        iyz="-9.9603E-19"
        izz="0.00057276" />
    </inertial>
    <visual>
      <origin
        xyz="0 0 0"
        rpy="0 0 0" />
      <geometry>
        <mesh
          filename="package://model_robot/meshes/left_wheel_link.STL" />
      </geometry>
      <material
        name="">
        <color
          rgba="0.019608 0 0 1" />
      </material>
    </visual>
    <collision>
      <origin
        xyz="0 0 0"
        rpy="0 0 0" />
      <geometry>
        <mesh
          filename="package://model_robot/meshes/left_wheel_link.STL" />
      </geometry>
    </collision>
  </link>
  <joint
    name="left_wheel_joint"
    type="continuous">
    <origin
      xyz="-0.11225 0.13 0"
      rpy="-1.5708 0.05745 0" />
    <parent
      link="base_link" />
    <child
      link="left_wheel_link" />
    <axis
      xyz="0 0 1" />
    <limit
      effort="10"
      velocity="20" />
    <dynamics
      damping="0.1"
      friction="0.1" />
  </joint>

  <link
    name="right_wheel_link">
    <inertial>
      <origin
        xyz="4.4409E-16 2.3245E-16 -0.04781"
        rpy="0 0 0" />
      <mass
        value="0.37174" />
      <inertia
        ixx="0.00039822"
        ixy="1.5059E-18"
        ixz="-3.6035E-19"
        iyy="0.00039822"
        iyz="-6.9788E-19"
        izz="0.00057276" />
    </inertial>
    <visual>
      <origin
        xyz="0 0 0"
        rpy="0 0 0" />
      <geometry>
        <mesh
          filename="package://model_robot/meshes/right_wheel_link.STL" />
      </geometry>
      <material
        name="">
        <color
          rgba="0.019608 0 0 -1" />
      </material>
    </visual>
    <collision>
      <origin
        xyz="0 0 0"
        rpy="0 0 0" />
      <geometry>
        <mesh
          filename="package://model_robot/meshes/right_wheel_link.STL" />
      </geometry>
    </collision>
  </link>
  <joint
    name="right_wheel_joint"
    type="continuous">
    <origin
      xyz="-0.11225 -0.13 0"
      rpy="-1.5708 0 0" />
    <parent
      link="base_link" />
    <child
      link="right_wheel_link" />
    <axis
      xyz="0 0 1" />
    <limit
      effort="10"
      velocity="20" />
    <dynamics
      damping="0.1"
      friction="0.1" />
  </joint>
  <link
    name="top_base_link">
    <inertial>
      <origin
        xyz="4.4409E-16 -1.5959E-16 0.043846"
        rpy="0 0 0" />
      <mass
        value="6.1261" />
      <inertia
        ixx="0.092849"
        ixy="2.2239E-18"
        ixz="-1.0728E-18"
        iyy="0.092849"
        iyz="-4.5642E-20"
        izz="0.18437" />
    </inertial>
    <visual>
      <origin
        xyz="0 0 0"
        rpy="0 0 0" />
      <geometry>
        <mesh
          filename="package://model_robot/meshes/top_base_link.STL" />
      </geometry>
      <material
        name="">
        <color
          rgba="0.48235 0.61176 1 1" />
      </material>
    </visual>
    <collision>
      <origin
        xyz="0 0 0"
        rpy="0 0 0" />
      <geometry>
        <mesh
          filename="package://model_robot/meshes/top_base_link.STL" />
      </geometry>
    </collision>
  </link>
  <joint
    name="top_base_joint"
    type="revolute">
    <origin
      xyz="0 0 0.03"
      rpy="0 0 0" />
    <parent
      link="base_link" />
    <child
      link="top_base_link" />
    <axis
      xyz="0 0 1" />
    <limit
      lower="0"
      upper="6.2832"
      effort="10"
      velocity="20" />
    <dynamics
      damping="0.1"
      friction="0.1" />
  </joint>

  <link
    name="lidar_link">
    <inertial>
      <origin
        xyz="0 -6.9389E-18 0.0099837"
        rpy="0 0 0" />
      <mass
        value="0.15681" />
      <inertia
        ixx="0.00010306"
        ixy="-6.0185E-36"
        ixz="-2.3099E-21"
        iyy="0.00010306"
        iyz="5.8547E-22"
        izz="0.00019569" />
    </inertial>
    <visual>
      <origin
        xyz="0 0 0"
        rpy="0 0 0" />
      <geometry>
        <mesh
          filename="package://model_robot/meshes/lidar_link.STL" />
      </geometry>
      <material
        name="">
        <color
          rgba="0.94118 0.16863 0 1" />
      </material>
    </visual>
    <collision>
      <origin
        xyz="0 0 0"
        rpy="0 0 0" />
      <geometry>
        <mesh
          filename="package://model_robot/meshes/lidar_link.STL" />
      </geometry>
    </collision>
  </link>
  <joint
    name="lidar_joint"
    type="continuous">
    <origin
      xyz="0.18 0 0.03"
      rpy="0 0 0" />
    <parent
      link="base_link" />
    <child
      link="lidar_link" />
    <axis
      xyz="0 0 1" />
    <limit
      effort="100"
      velocity="100" />
    <dynamics
      damping="0.1"
      friction="0.1" />
  </joint>

  <ros2_control name="diff_offset_robot_control" type="system">
    <hardware>
      <plugin>gazebo_ros2_control/GazeboSystem</plugin>
    </hardware>

    <joint name="left_wheel_joint">
      <command_interface name="velocity"/>
      <state_interface name="position"/>
      <state_interface name="velocity"/>
    </joint>

    <joint name="right_wheel_joint">
      <command_interface name="velocity"/>
      <state_interface name="position"/>
      <state_interface name="velocity"/>
    </joint>

    <joint name="top_base_joint">
      <command_interface name="velocity"/>
      <state_interface name="position"/>
      <state_interface name="velocity"/>
    </joint>
  </ros2_control>

  <gazebo>
    <plugin name="gazebo_lidar_joint_state" filename="libgazebo_ros_joint_state_publisher.so">
      <update_rate>100</update_rate>
      <joint_name>lidar_joint</joint_name>
    </plugin>

    <plugin name="gazebo_ros2_control" filename="libgazebo_ros2_control.so">
      <parameters>$(find model_robot)/config/ros2_controller.yaml</parameters>
    </plugin>
  </gazebo>

</robot>
