<?xml version="1.0" encoding="utf-8"?>

<robot
  name="diff_offset_robot">
  <link
    name="base_link">
    <inertial>
      <origin
        xyz="0.0077925 1.382E-07 0.0044813"
        rpy="0 0 0" />
      <mass
        value="16.766" />
      <inertia
        ixx="0.17714"
        ixy="-2.225E-17"
        ixz="-0.0072719"
        iyy="0.29215"
        iyz="1.8084E-15"
        izz="0.4637" />
    </inertial>
    <visual>
      <origin
        xyz="0 0 0"
        rpy="0 0 0" />
      <geometry>
        <mesh
          filename="package://model_robot/meshes/base_link.STL" />
      </geometry>
      <material
        name="">
        <color
          rgba="0.86667 0.9098 1 1" />
      </material>
    </visual>
    <collision>
      <origin
        xyz="0 0 0"
        rpy="0 0 0" />
      <geometry>
        <mesh
          filename="package://model_robot/meshes/base_link.STL" />
      </geometry>
    </collision>
  </link>
  <link
    name="left_wheel_link">
    <inertial>
      <origin
        xyz="2.2204E-16 -7.7716E-16 0.04781"
        rpy="0 0 0" />
      <mass
        value="0.37174" />
      <inertia
        ixx="0.00039822"
        ixy="6.9118E-19"
        ixz="4.4212E-19"
        iyy="0.00039822"
        iyz="-2.2832E-18"
        izz="0.00057276" />
    </inertial>
    <visual>
      <origin
        xyz="0 0 0"
        rpy="0 0 0" />
      <geometry>
        <mesh
          filename="package://model_robot/meshes/left_wheel_link.STL" />
      </geometry>
      <material
        name="">
        <color
          rgba="0.019608 0 0 1" />
      </material>
    </visual>
    <collision>
      <origin
        xyz="0 0 0"
        rpy="0 0 0" />
      <geometry>
        <mesh
          filename="package://model_robot/meshes/left_wheel_link.STL" />
      </geometry>
    </collision>
  </link>
  <joint
    name="left_wheel_joint"
    type="continuous">
    <origin
      xyz="-0.11225 0.13 0"
      rpy="1.5708 0.57871 3.1416" />
    <parent
      link="base_link" />
    <child
      link="left_wheel_link" />
    <axis
      xyz="0 0 1" />
    <limit
      effort="50"
      velocity="20" />
    <dynamics
      damping="0.1"
      friction="0.1" />
  </joint>
  <link
    name="right_wheel_link">
    <inertial>
      <origin
        xyz="6.6613E-16 -2.2204E-16 -0.04781"
        rpy="0 0 0" />
      <mass
        value="0.37174" />
      <inertia
        ixx="0.00039822"
        ixy="-2.7444E-19"
        ixz="3.7384E-19"
        iyy="0.00039822"
        iyz="3.2089E-19"
        izz="0.00057276" />
    </inertial>
    <visual>
      <origin
        xyz="0 0 0"
        rpy="0 0 0" />
      <geometry>
        <mesh
          filename="package://model_robot/meshes/right_wheel_link.STL" />
      </geometry>
      <material
        name="">
        <color
          rgba="0.019608 0 0 1" />
      </material>
    </visual>
    <collision>
      <origin
        xyz="0 0 0"
        rpy="0 0 0" />
      <geometry>
        <mesh
          filename="package://model_robot/meshes/right_wheel_link.STL" />
      </geometry>
    </collision>
  </link>
  <joint
    name="right_wheel_joint"
    type="continuous">
    <origin
      xyz="-0.11225 -0.13 0"
      rpy="-1.5708 -0.061252 0" />
    <parent
      link="base_link" />
    <child
      link="right_wheel_link" />
    <axis
      xyz="0 0 1" />
    <limit
      effort="50"
      velocity="20" />
    <dynamics
      damping="0.1"
      friction="0.1" />
  </joint>
  <link
    name="lidar_link">
    <inertial>
      <origin
        xyz="-2.22044604925031E-16 0 0.00998372049732055"
        rpy="0 0 0" />
      <mass
        value="0.194447333272832" />
      <inertia
        ixx="0.000127792042048439"
        ixy="-3.36102673470719E-21"
        ixz="1.19867346730935E-18"
        iyy="0.000127792042048439"
        iyz="1.19874708938594E-18"
        izz="0.000242659502252698" />
    </inertial>
    <visual>
      <origin
        xyz="0 0 0"
        rpy="0 0 0" />
      <geometry>
        <mesh
          filename="package://model_robot/meshes/lidar_link.STL" />
      </geometry>
      <material
        name="">
        <color
          rgba="0.698039215686274 0.698039215686274 0.698039215686274 1" />
      </material>
    </visual>
    <collision>
      <origin
        xyz="0 0 0"
        rpy="0 0 0" />
      <geometry>
        <mesh
          filename="package://model_robot/meshes/lidar_link.STL" />
      </geometry>
    </collision>
  </link>
  <joint
    name="lidar_joint"
    type="continuous">
    <origin
      xyz="0.18 0 0.03"
      rpy="0 0 0" />
    <parent
      link="base_link" />
    <child
      link="lidar_link" />
    <axis
      xyz="0 0 1" />
    <limit
      effort="10"
      velocity="20" />
    <dynamics
      damping="0.1"
      friction="0.1" />
  </joint>
  <link
    name="top_base_link">
    <inertial>
      <origin
        xyz="8.8818E-16 8.8818E-16 0.043846"
        rpy="0 0 0" />
      <mass
        value="16.54" />
      <inertia
        ixx="0.25069"
        ixy="4.8639E-18"
        ixz="2.5866E-15"
        iyy="0.25069"
        iyz="2.5916E-15"
        izz="0.4978" />
    </inertial>
    <visual>
      <origin
        xyz="0 0 0"
        rpy="0 0 0" />
      <geometry>
        <mesh
          filename="package://model_robot/meshes/top_base_link.STL" />
      </geometry>
      <material
        name="">
        <color
          rgba="0.86667 0.9098 1 1" />
      </material>
    </visual>
    <collision>
      <origin
        xyz="0 0 0"
        rpy="0 0 0" />
      <geometry>
        <mesh
          filename="package://model_robot/meshes/top_base_link.STL" />
      </geometry>
    </collision>
  </link>
  <joint
    name="top_base_joint"
    type="revolute">
    <origin
      xyz="0 0 0.03"
      rpy="0 0 0" />
    <parent
      link="base_link" />
    <child
      link="top_base_link" />
    <axis
      xyz="0 0 1" />
    <limit
      lower="0"
      upper="6.28"
      effort="10"
      velocity="20" />
    <dynamics
      damping="0.1"
      friction="0.1" />
  </joint>
  <link
    name="body_wheel_link">
    <inertial>
      <origin
        xyz="0.0012182 3.9726E-05 0.012909"
        rpy="0 0 0" />
      <mass
        value="0.067446" />
      <inertia
        ixx="1.7013E-05"
        ixy="1.4706E-07"
        ixz="1.1675E-07"
        iyy="1.2508E-05"
        iyz="3.8073E-09"
        izz="1.9263E-05" />
    </inertial>
    <visual>
      <origin
        xyz="0 0 0"
        rpy="0 0 0" />
      <geometry>
        <mesh
          filename="package://model_robot/meshes/body_wheel_link.STL" />
      </geometry>
      <material
        name="">
        <color
          rgba="0.77647 0.75686 0.73725 1" />
      </material>
    </visual>
    <collision>
      <origin
        xyz="0 0 0"
        rpy="0 0 0" />
      <geometry>
        <mesh
          filename="package://model_robot/meshes/body_wheel_link.STL" />
      </geometry>
    </collision>
  </link>
  <joint
    name="body_wheel_joint"
    type="continuous">
    <origin
      xyz="0.18 0 -0.015"
      rpy="3.1416 0 0" />
    <parent
      link="base_link" />
    <child
      link="body_wheel_link" />
    <axis
      xyz="0 0 1" />
    <limit
      effort="10"
      velocity="20" />
    <dynamics
      damping="0.01"/>
  </joint>
  <link
    name="caster_wheel_link">
    <inertial>
      <origin
        xyz="-2.2204E-16 2.2204E-16 0"
        rpy="0 0 0" />
      <mass
        value="0.034498" />
      <inertia
        ixx="5.4969E-06"
        ixy="-6.3793E-23"
        ixz="2.4265E-08"
        iyy="5.4961E-06"
        iyz="-1.9562E-21"
        izz="6.2402E-06" />
    </inertial>
    <visual>
      <origin
        xyz="0 0 0"
        rpy="0 0 0" />
      <geometry>
        <mesh
          filename="package://model_robot/meshes/caster_wheel_link.STL" />
      </geometry>
      <material
        name="">
        <color
          rgba="0.1098 0.1098 0.1098 1" />
      </material>
    </visual>
    <collision>
      <origin
        xyz="0 0 0"
        rpy="0 0 0" />
      <geometry>
        <mesh
          filename="package://model_robot/meshes/caster_wheel_link.STL" />
      </geometry>
    </collision>
  </link>
  <joint
    name="caster_wheel_joint"
    type="continuous">
    <origin
      xyz="0.0079957 0.00026075 0.023"
      rpy="1.5708 0 0" />
    <parent
      link="body_wheel_link" />
    <child
      link="caster_wheel_link" />
    <axis
      xyz="-0.032594 0 -0.99947" />
    <limit
      effort="10"
      velocity="20" />
  </joint>
  <ros2_control name="diff_offset_robot_control" type="system">
    <hardware>
      <plugin>gazebo_ros2_control/GazeboSystem</plugin>
    </hardware>

    <joint name="left_wheel_joint">
      <command_interface name="velocity"/>
      <state_interface name="position"/>
      <state_interface name="velocity"/>
    </joint>

    <joint name="right_wheel_joint">
      <command_interface name="velocity"/>
      <state_interface name="position"/>
      <state_interface name="velocity"/>
    </joint>

    <joint name="top_base_joint">
      <command_interface name="velocity"/>
      <state_interface name="position"/>
      <state_interface name="velocity"/>
    </joint>
  </ros2_control>

  <gazebo>
    <plugin name="gazebo_lidar_joint_state" filename="libgazebo_ros_joint_state_publisher.so">
      <update_rate>100</update_rate>
      <joint_name>lidar_joint</joint_name>
      <joint_name>body_wheel_joint</joint_name>
      <joint_name>caster_wheel_joint</joint_name>
    </plugin>

    <plugin name="gazebo_ros2_control" filename="libgazebo_ros2_control.so">
      <parameters>$(find model_robot)/config/ros2_controller.yaml</parameters>
    </plugin>
  </gazebo>

  <gazebo>
    <plugin name="p3d_base_controller" filename="libgazebo_ros_p3d.so">
      <ros>
        <namespace>/</namespace>
        <remapping>odom:=ground_truth/odom</remapping>
      </ros>
      <body_name>base_link</body_name>
      <frame_name>world</frame_name>
      <update_rate>50.0</update_rate>
      <xyz_offset>0 0 0</xyz_offset>
      <rpy_offset>0 0 0</rpy_offset>
      <gaussian_noise>0.0</gaussian_noise>
    </plugin>
  </gazebo>
  
</robot>
