<!-- ?xml version="1.0" encoding="utf-8"? -->
<!-- This URDF was automatically created by SolidWorks to URDF Exporter! Originally created by Stephen Brawner (brawner@gmail.com) 
     Commit Version: 1.6.0-4-g7f85cfe  Build Version: 1.6.7995.38578
     For more information, please see http://wiki.ros.org/sw_urdf_exporter -->
<robot
  name="diff_offset_robot">
  <link
    name="base_link">
    <inertial>
      <origin
        xyz="0.00767413610313483 -1.59594559789866E-16 0.0244882600344697"
        rpy="0 0 0" />
      <mass
        value="6.20721211987107" />
      <inertia
        ixx="0.065603714804586"
        ixy="-2.62715981130129E-17"
        ixz="-0.00271747552637359"
        iyy="0.107958443318796"
        iyz="1.27853406126115E-18"
        izz="0.1714956110287" />
    </inertial>
    <visual>
      <origin
        xyz="0 0 0"
        rpy="0 0 0" />
      <geometry>
        <mesh
          filename="package://model_robot/meshes/base_link.STL" />
      </geometry>
      <material
        name="">
        <color
          rgba="0.792156862745098 0.819607843137255 0.933333333333333 1" />
      </material>
    </visual>
    <collision>
      <origin
        xyz="0 0 0"
        rpy="0 0 0" />
      <geometry>
        <mesh
          filename="package://model_robot/meshes/base_link.STL" />
      </geometry>
    </collision>
  </link>
  <link
    name="left_wheel_link">
    <inertial>
      <origin
        xyz="0 1.3115E-15 0.04781"
        rpy="0 0 0" />
      <mass
        value="0.37174" />
      <inertia
        ixx="0.00039822"
        ixy="-3.0493E-19"
        ixz="-3.7264E-20"
        iyy="0.00039822"
        iyz="1.2533E-18"
        izz="0.00057276" />
    </inertial>
    <visual>
      <origin
        xyz="0 0 0"
        rpy="0 0 0" />
      <geometry>
        <mesh
          filename="package://model_robot/meshes/left_wheel_link.STL" />
      </geometry>
      <material
        name="">
        <color
          rgba="0.019608 0 0 1" />
      </material>
    </visual>
    <collision>
      <origin
        xyz="0 0 0"
        rpy="0 0 0" />
      <geometry>
        <mesh
          filename="package://model_robot/meshes/left_wheel_link.STL" />
      </geometry>
    </collision>
  </link>
  <joint
    name="left_wheel_joint"
    type="continuous">
    <origin
      xyz="-0.11225 0.13 0.02"
      rpy="-1.5708 0.05745 0" />
    <parent
      link="base_link" />
    <child
      link="left_wheel_link" />
    <axis
      xyz="0 0 1" />
    <limit
      effort="100"
      velocity="100" />
    <dynamics
      damping="0.1"
      friction="0.1" />
  </joint>
  <link
    name="right_wheel_link">
    <inertial>
      <origin
        xyz="4.4409E-16 3.6429E-16 -0.04781"
        rpy="0 0 0" />
      <mass
        value="0.37174" />
      <inertia
        ixx="0.00039822"
        ixy="1.7549E-18"
        ixz="-2.7572E-19"
        iyy="0.00039822"
        iyz="7.3638E-20"
        izz="0.00057276" />
    </inertial>
    <visual>
      <origin
        xyz="0 0 0"
        rpy="0 0 0" />
      <geometry>
        <mesh
          filename="package://model_robot/meshes/right_wheel_link.STL" />
      </geometry>
      <material
        name="">
        <color
          rgba="0.019608 0 0 1" />
      </material>
    </visual>
    <collision>
      <origin
        xyz="0 0 0"
        rpy="0 0 0" />
      <geometry>
        <mesh
          filename="package://model_robot/meshes/right_wheel_link.STL" />
      </geometry>
    </collision>
  </link>
  <joint
    name="right_wheel_joint"
    type="continuous">
    <origin
      xyz="-0.11225 -0.13 0.02"
      rpy="-1.5708 0 0" />
    <parent
      link="base_link" />
    <child
      link="right_wheel_link" />
    <axis
      xyz="0 0 1" />
    <limit
      effort="100"
      velocity="100" />
    <dynamics
      damping="0.1"
      friction="0.1" />
  </joint>
  <link
    name="top_base_link">
    <inertial>
      <origin
        xyz="4.4409E-16 -1.6653E-16 0.043846"
        rpy="0 0 0" />
      <mass
        value="6.1261" />
      <inertia
        ixx="0.092849"
        ixy="2.2239E-18"
        ixz="6.6189E-19"
        iyy="0.092849"
        iyz="-1.3571E-19"
        izz="0.18437" />
    </inertial>
    <visual>
      <origin
        xyz="0 0 0"
        rpy="0 0 0" />
      <geometry>
        <mesh
          filename="package://model_robot/meshes/top_base_link.STL" />
      </geometry>
      <material
        name="">
        <color
          rgba="0.48235 0.61176 1 1" />
      </material>
    </visual>
    <collision>
      <origin
        xyz="0 0 0"
        rpy="0 0 0" />
      <geometry>
        <mesh
          filename="package://model_robot/meshes/top_base_link.STL" />
      </geometry>
    </collision>
  </link>
  <joint
    name="top_base_joint"
    type="revolute">
    <origin
      xyz="0 0 0.05"
      rpy="0 0 0" />
    <parent
      link="base_link" />
    <child
      link="top_base_link" />
    <axis
      xyz="0 0 1" />
    <limit
      lower="0"
      upper="6.2832"
      effort="100"
      velocity="100" />
    <dynamics
      damping="0.1"
      friction="0.1" />
  </joint>
  <link
    name="lidar_link">
    <inertial>
      <origin
        xyz="0 -6.9389E-18 0.0099837"
        rpy="0 0 0" />
      <mass
        value="0.15681" />
      <inertia
        ixx="0.00010306"
        ixy="6.7763E-21"
        ixz="-1.185E-21"
        iyy="0.00010306"
        iyz="2.1885E-23"
        izz="0.00019569" />
    </inertial>
    <visual>
      <origin
        xyz="0 0 0"
        rpy="0 0 0" />
      <geometry>
        <mesh
          filename="package://model_robot/meshes/lidar_link.STL" />
      </geometry>
      <material
        name="">
        <color
          rgba="0.94118 0.16863 0 1" />
      </material>
    </visual>
    <collision>
      <origin
        xyz="0 0 0"
        rpy="0 0 0" />
      <geometry>
        <mesh
          filename="package://model_robot/meshes/lidar_link.STL" />
      </geometry>
    </collision>
  </link>
  <joint
    name="lidar_joint"
    type="continuous">
    <origin
      xyz="0.18 0 0.05"
      rpy="0 0 0" />
    <parent
      link="base_link" />
    <child
      link="lidar_link" />
    <axis
      xyz="0 0 1" />
    <limit
      effort="100"
      velocity="100" />
    <dynamics
      damping="0.1"
      friction="0.1" />
  </joint>
  <link
    name="body_wheel_link">
    <inertial>
      <origin
        xyz="0.0039086 -6.4483E-06 0.0095064"
        rpy="0 0 0" />
      <mass
        value="0.038337" />
      <inertia
        ixx="6.4036E-06"
        ixy="9.6169E-12"
        ixz="-8.202E-07"
        iyy="6.8878E-06"
        iyz="4.6142E-11"
        izz="8.465E-06" />
    </inertial>
    <visual>
      <origin
        xyz="0 0 0"
        rpy="0 0 0" />
      <geometry>
        <mesh
          filename="package://model_robot/meshes/body_wheel_link.STL" />
      </geometry>
      <material
        name="">
        <color
          rgba="0.77647 0.75686 0.73725 1" />
      </material>
    </visual>
    <collision>
      <origin
        xyz="0 0 0"
        rpy="0 0 0" />
      <geometry>
        <mesh
          filename="package://model_robot/meshes/body_wheel_link.STL" />
      </geometry>
    </collision>
  </link>
  <joint
    name="body_wheel_joint"
    type="continuous">
    <origin
      xyz="0.125 0 0.004"
      rpy="3.1416 0 0.0019842" />
    <parent
      link="base_link" />
    <child
      link="body_wheel_link" />
    <axis
      xyz="0 0 1" />
    <limit
      effort="100"
      velocity="100" />
    <dynamics
      damping="0.1"
      friction="0.1" />
  </joint>
  <link
    name="caster_wheel_link">
    <inertial>
      <origin
        xyz="-1.1102E-16 5.5511E-17 0"
        rpy="0 0 0" />
      <mass
        value="0.01313" />
      <inertia
        ixx="1.3177E-06"
        ixy="-1.0588E-22"
        ixz="9.6573E-23"
        iyy="1.3177E-06"
        iyz="-1.5696E-22"
        izz="1.8956E-06" />
    </inertial>
    <visual>
      <origin
        xyz="0 0 0"
        rpy="0 0 0" />
      <geometry>
        <mesh
          filename="package://model_robot/meshes/caster_wheel_link.STL" />
      </geometry>
      <material
        name="">
        <color
          rgba="0.25098 0.25098 0.25098 1" />
      </material>
    </visual>
    <collision>
      <origin
        xyz="0 0 0"
        rpy="0 0 0" />
      <geometry>
        <mesh
          filename="package://model_robot/meshes/caster_wheel_link.STL" />
      </geometry>
    </collision>
  </link>
  <joint
    name="caster_wheel_joint"
    type="continuous">
    <origin
      xyz="0.016 0 0.023"
      rpy="1.5708 -0.40647 0" />
    <parent
      link="body_wheel_link" />
    <child
      link="caster_wheel_link" />
    <axis
      xyz="0 0 1" />
    <limit
      effort="100"
      velocity="100" />
    <dynamics
      damping="0.1"
      friction="0.1" />
  </joint>

  <gazebo>
    <plugin name="two_wheeled_robot_diff_drive" filename="libgazebo_ros_diff_drive.so">
 
      <update_rate>100</update_rate>
      
      <!-- wheels -->
      <left_joint>left_wheel_joint</left_joint>
      <right_joint>right_wheel_joint</right_joint>
 
      <!-- kinematics -->
      <wheel_separation>0.36</wheel_separation>
      <wheel_diameter>0.11</wheel_diameter>
 
      <!-- limits -->
      <max_wheel_torque>20</max_wheel_torque>
      <max_wheel_acceleration>20.0</max_wheel_acceleration>
 
      <!-- Receive velocity commands on this ROS topic -->
      <command_topic>cmd_vel</command_topic>
 
      <!-- output -->
      <!-- When false, publish no wheel odometry data to a ROS topic -->
      <publish_odom>true</publish_odom>
 
      <!-- When true, publish coordinate transform from odom to base_footprint -->
      <!-- I usually use the robot_localization package to publish this transform -->  
      <publish_odom_tf>true</publish_odom_tf>
     
      <!-- When true, publish coordinate transform from base_link to the wheels -->
      <!-- The robot_state_publisher package is often used to publish this transform -->  
      <publish_wheel_tf>true</publish_wheel_tf>
 
      <odometry_topic>odom</odometry_topic>
      <odometry_frame>odom_link</odometry_frame>
      <robot_base_frame>base_link</robot_base_frame>
 
      <odometry_source>1</odometry_source>
      <ros>
        <remapping>odom:=wheel/odometry</remapping>
      </ros>
    </plugin>
  </gazebo>

  <gazebo>
    <plugin name="gazebo_ros_joint_state_publisher"
        filename="libgazebo_ros_joint_state_publisher.so">
        <update_rate>100</update_rate>
        <joint_name>top_base_joint</joint_name>
        <joint_name>lidar_joint</joint_name>
        <joint_name>body_wheel_joint</joint_name>
        <joint_name>caster_wheel_joint</joint_name>
    </plugin>
  </gazebo>

</robot>
